Workbook
Name Data: 'Master Data Lot1'!$A$1:$T$1
Name Data: 'Master Data Lot2'!$A$1:$T$92
Name Data2: #REF!

Sheet information
B4: Design | E4: Procurement | H4: Construction/Installation | K4: Inspection
B5: Outline | C5: Definitive Design | D5: Detail Design | E5: Pre-PR | F5: PO/WO | G5: Delivery | H5: Start | I5: WIP | J5: Complete | K5: Inspection | L5: Punch list | M5: Closed

Sheet 00 MASTER WORK REGISTER
B1: MASTER WORK REGISTER
A3: No | B3: Type of Work | C3: Work Code | D3: Lot No. | E3: System | F3: LV1 | G3: LV2 | H3: Description/Title | I3: CK | J3: Location | L3: Submission No. | M3: Ex | N3: Note
A4: 1 | B4: =IF(G4<>"",E4&F4&"."&G4,E4&F4) -> GEN1 | C4: DN01B1700001 | D4: Lot01 | E4: GEN | F4: 1 | H4: Rooms and Building Service Systems Modification in Stations Area | I4: - | K4: Station | L4: MDW-39246-60 | M4: 46235 | O4: =COUNTIF('02 Design'!$C$5:$C$366,'00 MASTER WORK REGISTER'!$B4) -> 10
A5: 2 | B5: =IF(G5<>"",E5&F5&"."&G5,E5&F5) -> GEN1.1 | C5: DN01B1700001 | D5: Lot01 | E5: GEN | F5: 1 | G5: 1 | H5: Power Outlet Installation in SOR, Ticket Office and Cash Handling for OR13 - OR17 | I5: - | K5: Station | L5: MDW-39246 | M5: 46235 | O5: =COUNTIF('02 Design'!$C$5:$C$366,'00 MASTER WORK REGISTER'!$B5) -> 1
A6: 3 | B6: =IF(G6<>"",E6&F6&"."&G6,E6&F6) -> GEN1.2 | C6: DN01B1700001 | D6: Lot01 | E6: GEN | F6: 1 | G6: 2 | H6: Power Outlet Installation in SOR, Ticket Office and Cash Handling for OR18 - OR22 | I6: - | K6: Station | L6: MDW-39247 | M6: 46235 | O6: =COUNTIF('02 Design'!$C$5:$C$366,'00 MASTER WORK REGISTER'!$B6) -> 1
A7: 4 | B7: =IF(G7<>"",E7&F7&"."&G7,E7&F7) -> GEN1.3 | C7: DN01B1700001 | D7: Lot01 | E7: GEN | F7: 1 | G7: 3 | H7: Power Outlet Installation in SOR, Ticket Office and Cash Handling for OR18 - OR22 | I7: - | K7: Station | L7: MDW-39247 | M7: 46235 | O7: =COUNTIF('02 Design'!$C$5:$C$366,'00 MASTER WORK REGISTER'!$B7) -> 1
A8: 5 | B8: =IF(G8<>"",E8&F8&"."&G8,E8&F8) -> GEN1.4 | C8: DN01B1700001 | D8: Lot01 | E8: GEN | F8: 1 | G8: 4 | H8: Power Outlet Installation in SOR, Ticket Office and Cash Handling for OR23 - OR29 | I8: - | K8: Station | L8: MDW-39248 | M8: 46235 | O8: =COUNTIF('02 Design'!$C$5:$C$366,'00 MASTER WORK REGISTER'!$B8) -> 1
A9: 6 | B9: =IF(G9<>"",E9&F9&"."&G9,E9&F9) -> GEN1.5 | C9: DN01B1700001 | D9: Lot01 | E9: GEN | F9: 1 | G9: 5 | H9: Power Outlet Installation in SOR, Ticket Office and Cash Handling for OR23 - OR29 | I9: - | K9: Station | L9: MDW-39248 | M9: 46235 | O9: =COUNTIF('02 Design'!$C$5:$C$366,'00 MASTER WORK REGISTER'!$B9) -> 1
A10: 7 | B10: =IF(G10<>"",E10&F10&"."&G10,E10&F10) -> GEN1.6 | C10: DN01B1700001 | D10: Lot01 | E10: GEN | F10: 1 | G10: 6 | H10: SOR Counter and Workstation Hanging Support Installation on East Section | I10: - | K10: Station | L10: MDW-39249 | M10: 46235 | O10: =COUNTIF('02 Design'!$C$5:$C$366,'00 MASTER WORK REGISTER'!$B10) -> 1
A11: 8 | B11: =IF(G11<>"",E11&F11&"."&G11,E11&F11) -> GEN1.7 | C11: DN01B1700001 | D11: Lot01 | E11: GEN | F11: 1 | G11: 7 | H11: Ticket Office Modification on East Section | I11: - | K11: Station | L11: MDW-39250 | M11: 46235 | N11: งานจบ ส่ง TP แล้ว | O11: =COUNTIF('02 Design'!$C$5:$C$366,'00 MASTER WORK REGISTER'!$B11) -> 1
A12: 9 | B12: =IF(G12<>"",E12&F12&"."&G12,E12&F12) -> GEN1.10 | C12: DN01B1700001 | D12: Lot01 | E12: GEN | F12: 1 | G12: 10 | H12: Modification of Eletrical System in Telecommunication Room at OR14 | I12: - | K12: Station | L12: MDW-39251 | M12: 46235 | O12: =COUNTIF('02 Design'!$C$5:$C$366,'00 MASTER WORK REGISTER'!$B12) -> 1
A13: 10 | B13: =IF(G13<>"",E13&F13&"."&G13,E13&F13) -> GEN1.11 | C13: DN01B1700001 | D13: Lot01 | E13: GEN | F13: 1 | G13: 11 | H13: Modification of Fire Suppression System (N2) in Commerial Room at OR14 | I13: - | K13: Station | L13: MDW-39252 | M13: 46235 | O13: =COUNTIF('02 Design'!$C$5:$C$366,'00 MASTER WORK REGISTER'!$B13) -> 1
A14: 11 | B14: =IF(G14<>"",E14&F14&"."&G14,E14&F14) -> GEN1.12 | C14: DN01B1700001 | D14: Lot01 | E14: GEN | F14: 1 | G14: 12 | H14: Modification of Civil Work in Telecommunication Room at OR14 | I14: - | K14: Station | L14: MDW-39253 | M14: 46235 | O14: =COUNTIF('02 Design'!$C$5:$C$366,'00 MASTER WORK REGISTER'!$B14) -> 1
A15: 12 | B15: =IF(G15<>"",E15&F15&"."&G15,E15&F15) -> GEN1.13 | C15: DN01B1700001 | D15: Lot01 | E15: GEN | F15: 1 | G15: 13 | H15: Modification in Staff Mess Room at OR13-OR17 | I15: - | K15: Station | L15: MDW-39254 | M15: 46235 | O15: =COUNTIF('02 Design'!$C$5:$C$366,'00 MASTER WORK REGISTER'!$B15) -> 1
A16: 13 | B16: =IF(G16<>"",E16&F16&"."&G16,E16&F16) -> GEN1.14 | C16: DN01B1700001 | D16: Lot01 | E16: GEN | F16: 1 | G16: 14 | H16: Modification in Staff Mess Room at OR18-OR22 | I16: - | K16: Station | L16: MDW-39255 | M16: 46235 | O16: =COUNTIF('02 Design'!$C$5:$C$366,'00 MASTER WORK REGISTER'!$B16) -> 1
A17: 14 | B17: =IF(G17<>"",E17&F17&"."&G17,E17&F17) -> GEN1.15 | C17: DN01B1700001 | D17: Lot01 | E17: GEN | F17: 1 | G17: 15 | H17: Modification in Staff Mess Room at OR23-OR29 | I17: - | K17: Station | L17: MDW-39256 | M17: 46235 | O17: =COUNTIF('02 Design'!$C$5:$C$366,'00 MASTER WORK REGISTER'!$B17) -> 1
A18: 15 | B18: =IF(G18<>"",E18&F18&"."&G18,E18&F18) -> GEN1.16 | C18: DN01B1700001 | D18: Lot01 | E18: GEN | F18: 1 | G18: 16 | H18: Modification of Air Conditioning in CER and SER at OR13-OR19 | I18: - | K18: Station | L18: MDW-39257 | M18: 46235 | O18: =COUNTIF('02 Design'!$C$5:$C$366,'00 MASTER WORK REGISTER'!$B18) -> 1
A19: 16 | B19: =IF(G19<>"",E19&F19&"."&G19,E19&F19) -> GEN1.17 | C19: DN01B1700001 | D19: Lot01 | E19: GEN | F19: 1 | G19: 17 | H19: Modification of Air Conditioning in CER and SER at OR20-OR22 | I19: - | K19: Station | L19: MDW-39258 | M19: 46235 | O19: =COUNTIF('02 Design'!$C$5:$C$366,'00 MASTER WORK REGISTER'!$B19) -> 1
A20: 17 | B20: =IF(G20<>"",E20&F20&"."&G20,E20&F20) -> GEN1.19 | C20: DN01B1700001 | D20: Lot01 | E20: GEN | F20: 1 | G20: 19 | H20: Modification of Air Conditioning in CER and SER at OR23-OR29 | I20: - | K20: Station | L20: MDW-39259 | M20: 46235 | O20: =COUNTIF('02 Design'!$C$5:$C$366,'00 MASTER WORK REGISTER'!$B20) -> 1
A21: 18 | B21: =IF(G21<>"",E21&F21&"."&G21,E21&F21) -> GEN1.20 | C21: DN01B1700001 | D21: Lot01 | E21: GEN | F21: 1 | G21: 20 | H21: Modification of Air Conditioning in M&E Room at OCC Building | I21: - | K21: Depot | L21: MDW-39260 | M21: 46235 | O21: =COUNTIF('02 Design'!$C$5:$C$366,'00 MASTER WORK REGISTER'!$B21) -> 1
A22: 19 | B22: =IF(G22<>"",E22&F22&"."&G22,E22&F22) -> GEN2 | C22: DN01B1700002 | D22: Lot01 | E22: GEN | F22: 2 | H22: Rooms and Building Service Systems Modification in Depot Area | I22: - | K22: Depot | L22: MDW-39261 | M22: 46235 | O22: =COUNTIF('02 Design'!$C$5:$C$366,'00 MASTER WORK REGISTER'!$B22) -> 17
A23: 20 | B23: =IF(G23<>"",E23&F23&"."&G23,E23&F23) -> GEN3 | C23: DN01B1700003 | D23: Lot01 | E23: GEN | F23: 3 | H23: Cable Containment Modification | I23: - | K23: Station | L23: MDW-39200-31 | M23: 45805 | O23: =COUNTIF('02 Design'!$C$5:$C$366,'00 MASTER WORK REGISTER'!$B23) -> 32
A24: 21 | B24: =IF(G24<>"",E24&F24&"."&G24,E24&F24) -> GEN4 | C24: DN01B1700004 | D24: Lot01 | E24: GEN | F24: 4 | H24: Training Room and Workshop Room | I24: - | K24: Depot | L24: - | M24: 46113 | O24: =COUNTIF('02 Design'!$C$5:$C$366,'00 MASTER WORK REGISTER'!$B24) -> 2
A25: 22 | B25: =IF(G25<>"",E25&F25&"."&G25,E25&F25) -> GEN4.0 | C25: DN01B1700004 | D25: Lot01 | E25: GEN | F25: 4 | G25: 0 | H25: Modification Works for Training Room at Ratchada Station | I25: ประธาน | K25: BL | L25: MDW-39242 | M25: 46113 | O25: =COUNTIF('02 Design'!$C$5:$C$366,'00 MASTER WORK REGISTER'!$B25) -> 1
A26: 23 | B26: =IF(G26<>"",E26&F26&"."&G26,E26&F26) -> GEN4.1 | C26: DN01B1700004 | D26: Lot01 | E26: GEN | F26: 4 | G26: 1 | H26: AFC Training Room Modification - Civil & AR | I26: สหชาติ | J26: MWS | K26: Depot | L26: MDW-39244 | M26: 46255 | O26: =COUNTIF('02 Design'!$C$5:$C$366,'00 MASTER WORK REGISTER'!$B26) -> 1
A27: 24 | B27: =IF(G27<>"",E27&F27&"."&G27,E27&F27) -> GEN4.2 | C27: DN01B1700004 | D27: Lot01 | E27: GEN | F27: 4 | G27: 2 | H27: AFC Training Room Modification - Building Services | I27: ประธาน | J27: MWS | K27: Depot | L27: MDW-39245 | M27: 46255 | O27: =COUNTIF('02 Design'!$C$5:$C$366,'00 MASTER WORK REGISTER'!$B27) -> 1
A28: 25 | B28: =IF(G28<>"",E28&F28&"."&G28,E28&F28) -> GEN5 | C28: DN01B1700005 | D28: Lot01 | E28: GEN | F28: 5 | H28: Raised Floor | I28: สหชาติ | K28: Station | L28: MDW-39235 | M28: 46174 | O28: =COUNTIF('02 Design'!$C$5:$C$366,'00 MASTER WORK REGISTER'!$B28) -> 1
A29: 26 | B29: =IF(G29<>"",E29&F29&"."&G29,E29&F29) -> GEN6 | C29: DN01B1700006 | D29: Lot01 | E29: GEN | F29: 6 | H29: Wayside Cable Containment in Depot | I29: - | L29: MDW-39271 | M29: 46075 | O29: =COUNTIF('02 Design'!$C$5:$C$366,'00 MASTER WORK REGISTER'!$B29) -> 2
A30: 27 | B30: =IF(G30<>"",E30&F30&"."&G30,E30&F30) -> GEN6.1 | C30: DN01B1700006 | D30: Lot01 | E30: GEN | F30: 6 | G30: 1 | H30: PSY Wayside Cable Containment for 24 Kv Cable under the Depot slab | I30: ประธาน | L30: MDW-39269 | M30: 46075 | N30: CANCLE | O30: =COUNTIF('02 Design'!$C$5:$C$366,'00 MASTER WORK REGISTER'!$B30) -> 1
A31: 28 | B31: =IF(G31<>"",E31&F31&"."&G31,E31&F31) -> GEN6.2 | C31: DN01B1700006 | D31: Lot01 | E31: GEN | F31: 6 | G31: 2 | H31: COM/SIG Wayside Cable Containment in the Depot | I31: มนตรี/ประธาน | L31: MDW-39270 | M31: 46075 | N31: CANCLE | O31: =COUNTIF('02 Design'!$C$5:$C$366,'00 MASTER WORK REGISTER'!$B31) -> 1
A32: 29 | B32: =IF(G32<>"",E32&F32&"."&G32,E32&F32) -> GEN7 | C32: DN01B1700007 | D32: Lot01 | E32: GEN | F32: 7 | H32: Dangerous Waste Storage Building in Depot | I32: สหชาติ/ประธาน | L32: - | M32: 46285 | O32: =COUNTIF('02 Design'!$C$5:$C$366,'00 MASTER WORK REGISTER'!$B32) -> 0
A33: 30 | B33: =IF(G33<>"",E33&F33&"."&G33,E33&F33) -> GEN7.1 | C33: DN01B1700007 | D33: Lot01 | E33: GEN | F33: 7 | G33: 1 | H33: Dangerous Waste Storage Building in Depot - Civil & AR | I33: สหชาติ | L33: DWE-39024 | M33: 46285 | O33: =COUNTIF('02 Design'!$C$5:$C$366,'00 MASTER WORK REGISTER'!$B33) -> 1
A34: 31 | B34: =IF(G34<>"",E34&F34&"."&G34,E34&F34) -> GEN7.2 | C34: DN01B1700007 | D34: Lot01 | E34: GEN | F34: 7 | G34: 2 | H34: Dangerous Waste Storage Building in Depot - Building service | I34: ประธาน | L34: DWE-39025 | M34: 46285 | O34: =COUNTIF('02 Design'!$C$5:$C$366,'00 MASTER WORK REGISTER'!$B34) -> 1
A35: 32 | B35: =IF(G35<>"",E35&F35&"."&G35,E35&F35) -> GEN8 | C35: DN01B1700008 | D35: Lot01 | E35: GEN | F35: 8 | H35: General Waste Storage Building in Depot | I35: สหชาติ/ประธาน | L35: - | M35: 46285 | O35: =COUNTIF('02 Design'!$C$5:$C$366,'00 MASTER WORK REGISTER'!$B35) -> 0
A36: 33 | B36: =IF(G36<>"",E36&F36&"."&G36,E36&F36) -> GEN8.1 | C36: DN01B1700008 | D36: Lot01 | E36: GEN | F36: 8 | G36: 1 | H36: General Waste Storage Building in Depot - Civil & AR | I36: สหชาติ | L36: DWE-39026 | M36: 46285 | O36: =COUNTIF('02 Design'!$C$5:$C$366,'00 MASTER WORK REGISTER'!$B36) -> 1
A37: 34 | B37: =IF(G37<>"",E37&F37&"."&G37,E37&F37) -> GEN8.2 | C37: DN01B1700008 | D37: Lot01 | E37: GEN | F37: 8 | G37: 2 | H37: General Waste Storage Building in Depot - Building service | I37: ประธาน | L37: DWE-39025 | M37: 46285 | O37: =COUNTIF('02 Design'!$C$5:$C$366,'00 MASTER WORK REGISTER'!$B37) -> 1
A38: 35 | B38: =IF(G38<>"",E38&F38&"."&G38,E38&F38) -> GEN9 | C38: DN01B1700009 | D38: Lot01 | E38: GEN | F38: 9 | H38: Operation Support Equipment | I38: สมศักดิ์ | L38: DWE-39021 | M38: 46255 | O38: =COUNTIF('02 Design'!$C$5:$C$366,'00 MASTER WORK REGISTER'!$B38) -> 1
A39: 36 | B39: =IF(G39<>"",E39&F39&"."&G39,E39&F39) -> GEN10.1 | C39: DN01B1700010 | D39: Lot01 | E39: GEN | F39: 10 | G39: 1 | H39: Graphic and Signage Station | I39: สหชาติ | L39: GRS-39001-40 | M39: 46255 | O39: =COUNTIF('02 Design'!$C$5:$C$366,'00 MASTER WORK REGISTER'!$B39) -> 0
A40: 37 | B40: =IF(G40<>"",E40&F40&"."&G40,E40&F40) -> GEN10.2 | C40: DN01B1700010 | D40: Lot01 | E40: GEN | F40: 10 | G40: 2 | H40: Graphic and Signage Mainline & IVS,VS | I40: สหชาติ | L40: GRS-39001-40 | M40: 46255 | O40: =COUNTIF('02 Design'!$C$5:$C$366,'00 MASTER WORK REGISTER'!$B40) -> 0
A41: 38 | B41: =IF(G41<>"",E41&F41&"."&G41,E41&F41) -> GEN10.3 | C41: DN01B1700010 | D41: Lot01 | E41: GEN | F41: 10 | G41: 3 | H41: Graphic and Signage Depot | I41: สหชาติ | L41: GRS-39001-40 | M41: 46255 | O41: =COUNTIF('02 Design'!$C$5:$C$366,'00 MASTER WORK REGISTER'!$B41) -> 0
...

Sheet 01 Summary
L1: D | M1: 0.1 | O1: P | P1: 0.1 | R1: M | S1: 0.1 | U1: C&I | V1: 0.6 | X1: T | Y1: 0.05 | AA1: TP | AB1: 0.01 | AD1: I | AE1: 0.01 | AG1: TR | AH1: 0.03 | AK1: =M1+P1+S1+V1+Y1+AB1+AE1+AH1 -> 1
L2: Design | O2: Procurement | R2: Manufacturing / Delivery Process | U2: Construction/Installation | X2: T&C | AA2: Test Procedure | AD2: Inspection | AG2: Test Report | AP2: CV/AR | AQ2: E&M | AR2: CV/AR+E&M
B3: No. | C3: Design Submission | D3: Lot No. | E3: Code | F3: System | G3: Activity Name | H3: CK Responsible Person | I3: Priority | J3: Location | K3: Expected Completion Month | L3: Design (PLAN) | M3: Design (%) | N3: Design (Status) | O3: Procurement (PLAN) | P3: Procurement (%) | Q3: Procurement (Status) | R3: Manufacturing / Delivery Process (PLAN) | S3: Manufacturing / Delivery Process (%) | T3: Manufacturing / Delivery (Status) | U3: Construction /Installation (PLAN) | V3: Construction /Installation (%) | W3: Construction /Installation (Status) | X3: T&C (PLAN) | Y3: T&C (%) | Z3: T&C (Status) | AA3: Test Procedure (PLAN) | AB3: Test Procedure (%) | AC3: Test Procedure (Status) | AD3: Inspection (PLAN) | AE3: Inspection (%) | AF3: Inspection (Status) | AG3: Test Report (PLAN) | AH3: Test Report (%) | AI3: Test Report (Status) | AJ3: Forecast Finish | AK3: Overall (%) | AL3: Overall (Status) | AM3: Note | AN3: remark | AO3: Detail | AQ3: แผนก | AS3: de | AT3: pro | AU3: re
A4: 1 | B4: 1 | C4: =_xlfn.XLOOKUP($E4,'00 MASTER WORK REGISTER'!B:B,'00 MASTER WORK REGISTER'!L:L) -> MDW-39246-60 | D4: Lot01 | E4: GEN1 | F4: GEN | G4: =_xlfn.XLOOKUP($E4,'00 MASTER WORK REGISTER'!B:B,'00 MASTER WORK REGISTER'!H:H) -> Rooms and Building Service Systems Modification in Stations Area | H4: - | K4: =_xlfn.XLOOKUP($E4,'00 MASTER WORK REGISTER'!$B:$B,'00 MASTER WORK REGISTER'!$M:$M,"") -> 46235 | AK4: =IFERROR(SUMPRODUCT(($M$1:$AH$1),(M4:AH4))/SUMIF((M4:AH4),"<>",($M$1:$AH$1)),"") | AL4: =IF($AK4=1, "Completed", IF($K4<TODAY(), "Late", "On Schedule")) -> Late | AN4: =_xlfn.XLOOKUP($E4,'00 MASTER WORK REGISTER'!B:B,'00 MASTER WORK REGISTER'!N:N,"") -> 0 | AP4: =_xlfn.XLOOKUP($F4,#REF!,#REF!,"") -> #REF! | AS4: MDW-39246 | AT4: =_xlfn.XLOOKUP($AS4,'02 Design'!F:F,'02 Design'!AE:AE," ") -> MDW-69259 | AU4: =_xlfn.XLOOKUP($AS4,'02 Design'!F:F,'02 Design'!AF:AF," ") -> MDW-69260
A5: 2 | B5: 2 | C5: MDW-39246 | D5: Lot01 | E5: GEN1.1 | F5: GEN | G5: Power Outlet Installation in SOR, Ticket Office and Cash Handling for OR13 - OR17 | H5: ประธาน | K5: 46235 | L5: =O5-30 -> 46052 | M5: 1 | N5: =IF($M5=1, "Completed", IF($L5<TODAY(), "Late", "On Schedule")) -> Completed | O5: =U5-30 -> 46082 | P5: 1 | Q5: =IF($P5=1, "Completed", IF($O5<TODAY(), "Late", "On Schedule")) -> Completed | U5: 46112 | V5: 1 | W5: =IF($V5=1, "Completed", IF($U5<TODAY(), "Late", "On Schedule")) -> Completed | AA5: 46295 | AB5: 1 | AC5: =IF($AB5=1, "Completed", IF($AA5<TODAY(), "Late", "On Schedule")) -> Completed | AD5: 46326 | AE5: 1 | AF5: =IF($AE5=1, "Completed", IF($AD5<TODAY(), "Late", "On Schedule")) -> Completed | AG5: 46326 | AH5: 0 | AI5: =IF($AH5=1, "Completed", IF($AG5<TODAY(), "Late", "On Schedule")) -> On Schedule | AK5: =IFERROR(SUMPRODUCT(($M$1:$AH$1),(M5:AH5))/SUMIF((M5:AH5),"<>",($M$1:$AH$1)),"") -> 0.96470588 | AL5: =IF($AK5=1, "Completed", IF($K5<TODAY(), "Late", "On Schedule")) -> Late | AN5: =_xlfn.XLOOKUP($E5,'00 MASTER WORK REGISTER'!B:B,'00 MASTER WORK REGISTER'!N:N,"") -> 0 | AO5: เพิ่มปลั๊ก ที่ห้อง SOR/Ticket Office/Cash handling room | AS5: MDW-39246 | AT5: MDW-69259 | AU5: MDW-69260
A6: 3 | B6: 3 | C6: MDW-39247 | D6: Lot01 | E6: GEN1.2 | F6: GEN | G6: Power Outlet Installation in SOR, Ticket Office and Cash Handling for OR18 - OR22 | H6: ประธาน | K6: 46235 | L6: =O6-30 -> 46021 | M6: 1 | N6: =IF($M6=1, "Completed", IF($L6<TODAY(), "Late", "On Schedule")) -> Completed | O6: =U6-30 -> 46051 | P6: 1 | Q6: =IF($P6=1, "Completed", IF($O6<TODAY(), "Late", "On Schedule")) -> Completed | U6: 46081 | V6: 1 | W6: =IF($V6=1, "Completed", IF($U6<TODAY(), "Late", "On Schedule")) -> Completed | AA6: 46295 | AB6: 1 | AC6: =IF($AB6=1, "Completed", IF($AA6<TODAY(), "Late", "On Schedule")) -> Completed | AD6: 46326 | AE6: 1 | AF6: =IF($AE6=1, "Completed", IF($AD6<TODAY(), "Late", "On Schedule")) -> Completed | AG6: 46326 | AH6: 0 | AI6: =IF($AH6=1, "Completed", IF($AG6<TODAY(), "Late", "On Schedule")) -> On Schedule | AK6: =IFERROR(SUMPRODUCT(($M$1:$AH$1),(M6:AH6))/SUMIF((M6:AH6),"<>",($M$1:$AH$1)),"") -> 0.96470588 | AL6: =IF($AK6=1, "Completed", IF($K6<TODAY(), "Late", "On Schedule")) -> Late | AN6: =_xlfn.XLOOKUP($E6,'00 MASTER WORK REGISTER'!B:B,'00 MASTER WORK REGISTER'!N:N,"") -> 0 | AO6: เพิ่มปลั๊ก ที่ห้อง SOR/Ticket Office/Cash handling room | AS6: MDW-39247 | AT6: MDW-69259 | AU6: MDW-69261
A7: 4 | B7: 4 | C7: MDW-39248 | D7: Lot01 | E7: GEN1.3 | F7: GEN | G7: Power Outlet Installation in SOR, Ticket Office and Cash Handling for OR23 - OR29 | H7: ประธาน | K7: 46235 | L7: =O7-30 -> 46052 | M7: 1 | N7: =IF($M7=1, "Completed", IF($L7<TODAY(), "Late", "On Schedule")) -> Completed | O7: =U7-30 -> 46082 | P7: 1 | Q7: =IF($P7=1, "Completed", IF($O7<TODAY(), "Late", "On Schedule")) -> Completed | U7: 46112 | V7: 1 | W7: =IF($V7=1, "Completed", IF($U7<TODAY(), "Late", "On Schedule")) -> Completed | AA7: 46295 | AB7: 1 | AC7: =IF($AB7=1, "Completed", IF($AA7<TODAY(), "Late", "On Schedule")) -> Completed | AD7: 46326 | AE7: 1 | AF7: =IF($AE7=1, "Completed", IF($AD7<TODAY(), "Late", "On Schedule")) -> Completed | AG7: 46326 | AH7: 0 | AI7: =IF($AH7=1, "Completed", IF($AG7<TODAY(), "Late", "On Schedule")) -> On Schedule | AK7: =IFERROR(SUMPRODUCT(($M$1:$AH$1),(M7:AH7))/SUMIF((M7:AH7),"<>",($M$1:$AH$1)),"") -> 0.96470588 | AL7: =IF($AK7=1, "Completed", IF($K7<TODAY(), "Late", "On Schedule")) -> Late | AN7: =_xlfn.XLOOKUP($E7,'00 MASTER WORK REGISTER'!B:B,'00 MASTER WORK REGISTER'!N:N,"") -> 0 | AO7: เพิ่มปลั๊ก ที่ห้อง SOR/Ticket Office/Cash handling room | AS7: MDW-39248 | AT7: MDW-69259 | AU7: MDW-69262
A8: 5 | B8: 5 | C8: MDW-39252 | D8: Lot01 | E8: GEN1.4 | F8: GEN | G8: Modification of Fire Suppression System (N2) in Commerial Room at OR14 | H8: ประธาน | K8: 46235 | L8: =O8-30 -> 46021 | M8: 1 | N8: =IF($M8=1, "Completed", IF($L8<TODAY(), "Late", "On Schedule")) -> Completed | O8: =U8-30 -> 46051 | P8: 1 | Q8: =IF($P8=1, "Completed", IF($O8<TODAY(), "Late", "On Schedule")) -> Completed | U8: 46081 | V8: 1 | W8: =IF($V8=1, "Completed", IF($U8<TODAY(), "Late", "On Schedule")) -> Completed | AA8: 46295 | AB8: 1 | AC8: =IF($AB8=1, "Completed", IF($AA8<TODAY(), "Late", "On Schedule")) -> Completed | AD8: 46326 | AE8: 1 | AF8: =IF($AE8=1, "Completed", IF($AD8<TODAY(), "Late", "On Schedule")) -> Completed | AG8: 46326 | AH8: 0 | AI8: =IF($AH8=1, "Completed", IF($AG8<TODAY(), "Late", "On Schedule")) -> On Schedule | AK8: =IFERROR(SUMPRODUCT(($M$1:$AH$1),(M8:AH8))/SUMIF((M8:AH8),"<>",($M$1:$AH$1)),"") -> 0.96470588 | AL8: =IF($AK8=1, "Completed", IF($K8<TODAY(), "Late", "On Schedule")) -> Late | AN8: =_xlfn.XLOOKUP($E8,'00 MASTER WORK REGISTER'!B:B,'00 MASTER WORK REGISTER'!N:N,"") -> 0 | AS8: MDW-39252 | AT8: MDW-69269 | AU8: MDW-69270
A9: 6 | B9: 6 | C9: MDW-39253 | D9: Lot01 | E9: GEN1.5 | F9: GEN | G9: Modification of Civil Work in Telecommunication Room at OR14 | H9: สหชาติ | K9: 46235 | L9: =O9-30 -> 46021 | M9: 1 | N9: =IF($M9=1, "Completed", IF($L9<TODAY(), "Late", "On Schedule")) -> Completed | O9: =U9-30 -> 46051 | P9: 1 | Q9: =IF($P9=1, "Completed", IF($O9<TODAY(), "Late", "On Schedule")) -> Completed | U9: 46081 | V9: 1 | W9: =IF($V9=1, "Completed", IF($U9<TODAY(), "Late", "On Schedule")) -> Completed | AA9: 46295 | AB9: 1 | AC9: =IF($AB9=1, "Completed", IF($AA9<TODAY(), "Late", "On Schedule")) -> Completed | AG9: 46326 | AH9: 0 | AI9: =IF($AH9=1, "Completed", IF($AG9<TODAY(), "Late", "On Schedule")) -> On Schedule | AK9: =IFERROR(SUMPRODUCT(($M$1:$AH$1),(M9:AH9))/SUMIF((M9:AH9),"<>",($M$1:$AH$1)),"") -> 0.96428571 | AL9: =IF($AK9=1, "Completed", IF($K9<TODAY(), "Late", "On Schedule")) -> Late | AN9: =_xlfn.XLOOKUP($E9,'00 MASTER WORK REGISTER'!B:B,'00 MASTER WORK REGISTER'!N:N,"") -> 0 | AS9: MDW-39253 | AT9: MDW-69271 | AU9: MDW-69272
A10: 7 | B10: 7 | C10: MDW-39254 | D10: Lot01 | E10: GEN1.6 | F10: GEN | G10: Modification in Staff Mess Room at OR13-OR17 | H10: ประธาน | K10: 46235 | L10: =O10-30 -> 46052 | M10: 1 | N10: =IF($M10=1, "Completed", IF($L10<TODAY(), "Late", "On Schedule")) -> Completed | O10: =U10-30 -> 46082 | P10: 1 | Q10: =IF($P10=1, "Completed", IF($O10<TODAY(), "Late", "On Schedule")) -> Completed | U10: 46112 | V10: 1 | W10: =IF($V10=1, "Completed", IF($U10<TODAY(), "Late", "On Schedule")) -> Completed | AA10: 46295 | AB10: 1 | AC10: =IF($AB10=1, "Completed", IF($AA10<TODAY(), "Late", "On Schedule")) -> Completed | AD10: 46326 | AE10: 1 | AF10: =IF($AE10=1, "Completed", IF($AD10<TODAY(), "Late", "On Schedule")) -> Completed | AG10: 46326 | AH10: 0 | AI10: =IF($AH10=1, "Completed", IF($AG10<TODAY(), "Late", "On Schedule")) -> On Schedule | AK10: =IFERROR(SUMPRODUCT(($M$1:$AH$1),(M10:AH10))/SUMIF((M10:AH10),"<>",($M$1:$AH$1)),"") -> 0.96470588 | AL10: =IF($AK10=1, "Completed", IF($K10<TODAY(), "Late", "On Schedule")) -> Late | AN10: =_xlfn.XLOOKUP($E10,'00 MASTER WORK REGISTER'!B:B,'00 MASTER WORK REGISTER'!N:N,"") -> 0 | AS10: MDW-39254 | AT10: MDW-69273 | AU10: MDW-69274
A11: 8 | B11: 8 | C11: MDW-39255 | D11: Lot01 | E11: GEN1.7 | F11: GEN | G11: Modification in Staff Mess Room at OR18-OR22 | H11: ประธาน | K11: 46235 | L11: =O11-30 -> 46235 | M11: 1 | N11: =IF($M11=1, "Completed", IF($L11<TODAY(), "Late", "On Schedule")) -> Completed | O11: =U11-30 -> 46265 | P11: 1 | Q11: =IF($P11=1, "Completed", IF($O11<TODAY(), "Late", "On Schedule")) -> Completed | U11: 46295 | V11: 1 | W11: =IF($V11=1, "Completed", IF($U11<TODAY(), "Late", "On Schedule")) -> Completed | AA11: 46295 | AB11: 1 | AC11: =IF($AB11=1, "Completed", IF($AA11<TODAY(), "Late", "On Schedule")) -> Completed | AD11: 46326 | AE11: 0 | AF11: =IF($AE11=1, "Completed", IF($AD11<TODAY(), "Late", "On Schedule")) -> On Schedule | AG11: 46326 | AH11: 0 | AI11: =IF($AH11=1, "Completed", IF($AG11<TODAY(), "Late", "On Schedule")) -> On Schedule | AK11: =IFERROR(SUMPRODUCT(($M$1:$AH$1),(M11:AH11))/SUMIF((M11:AH11),"<>",($M$1:$AH$1)),"") -> 0.95294118 | AL11: =IF($AK11=1, "Completed", IF($K11<TODAY(), "Late", "On Schedule")) -> Late | AN11: =_xlfn.XLOOKUP($E11,'00 MASTER WORK REGISTER'!B:B,'00 MASTER WORK REGISTER'!N:N,"") -> งานจบ ส่ง TP แล้ว | AS11: MDW-39255 | AT11: MDW-69273 | AU11: MDW-69275
A12: 9 | B12: 9 | C12: MDW-39256 | D12: Lot01 | E12: GEN1.8 | F12: GEN | G12: Modification in Staff Mess Room at OR23-OR29 | H12: ประธาน | K12: 46235 | L12: =O12-30 -> 46235 | M12: 1 | N12: =IF($M12=1, "Completed", IF($L12<TODAY(), "Late", "On Schedule")) -> Completed | O12: =U12-30 -> 46265 | P12: 1 | Q12: =IF($P12=1, "Completed", IF($O12<TODAY(), "Late", "On Schedule")) -> Completed | U12: 46295 | V12: 1 | W12: =IF($V12=1, "Completed", IF($U12<TODAY(), "Late", "On Schedule")) -> Completed | AA12: 46295 | AB12: 1 | AC12: =IF($AB12=1, "Completed", IF($AA12<TODAY(), "Late", "On Schedule")) -> Completed | AD12: 46356 | AE12: 0 | AF12: =IF($AE12=1, "Completed", IF($AD12<TODAY(), "Late", "On Schedule")) -> On Schedule | AG12: 46326 | AH12: 0 | AI12: =IF($AH12=1, "Completed", IF($AG12<TODAY(), "Late", "On Schedule")) -> On Schedule | AK12: =IFERROR(SUMPRODUCT(($M$1:$AH$1),(M12:AH12))/SUMIF((M12:AH12),"<>",($M$1:$AH$1)),"") -> 0.95294118 | AL12: =IF($AK12=1, "Completed", IF($K12<TODAY(), "Late", "On Schedule")) -> Late | AN12: =_xlfn.XLOOKUP($E12,'00 MASTER WORK REGISTER'!B:B,'00 MASTER WORK REGISTER'!N:N,"") | AS12: MDW-39256 | AT12: MDW-69273 | AU12: MDW-69276
A13: 10 | B13: 10 | C13: MDW-39257 | D13: Lot01 | E13: GEN1.9 | F13: GEN | G13: Modification of Air Conditioning in CER and SER at OR13-OR19 | H13: ประธาน | K13: 46235 | L13: =O13-30 -> 46235 | M13: 1 | N13: =IF($M13=1, "Completed", IF($L13<TODAY(), "Late", "On Schedule")) -> Completed | O13: =U13-30 -> 46265 | P13: 1 | Q13: =IF($P13=1, "Completed", IF($O13<TODAY(), "Late", "On Schedule")) -> Completed | U13: 46295 | V13: 0.99 | W13: =IF($V13=1, "Completed", IF($U13<TODAY(), "Late", "On Schedule")) -> Late | AA13: 46295 | AB13: 1 | AC13: =IF($AB13=1, "Completed", IF($AA13<TODAY(), "Late", "On Schedule")) -> Completed | AD13: 46356 | AE13: 0 | AF13: =IF($AE13=1, "Completed", IF($AD13<TODAY(), "Late", "On Schedule")) -> On Schedule | AG13: 46326 | AH13: 0 | AI13: =IF($AH13=1, "Completed", IF($AG13<TODAY(), "Late", "On Schedule")) -> On Schedule | AK13: =IFERROR(SUMPRODUCT(($M$1:$AH$1),(M13:AH13))/SUMIF((M13:AH13),"<>",($M$1:$AH$1)),"") -> 0.94588235 | AL13: =IF($AK13=1, "Completed", IF($K13<TODAY(), "Late", "On Schedule")) -> Late | AN13: =_xlfn.XLOOKUP($E13,'00 MASTER WORK REGISTER'!B:B,'00 MASTER WORK REGISTER'!N:N,"") | AS13: MDW-39257 | AT13: MDW-69277 | AU13: MDW-69278
A14: 11 | B14: 11 | C14: MDW-39258 | D14: Lot01 | E14: GEN1.10 | F14: GEN | G14: Modification of Air Conditioning in CER and SER at OR20-OR22 | H14: ประธาน | K14: 46235 | L14: =O14-30 -> 46235 | M14: 1 | N14: =IF($M14=1, "Completed", IF($L14<TODAY(), "Late", "On Schedule")) -> Completed | O14: =U14-30 -> 46265 | P14: 1 | Q14: =IF($P14=1, "Completed", IF($O14<TODAY(), "Late", "On Schedule")) -> Completed | U14: 46295 | V14: 0.99 | W14: =IF($V14=1, "Completed", IF($U14<TODAY(), "Late", "On Schedule")) -> Late | AA14: 46295 | AB14: 1 | AC14: =IF($AB14=1, "Completed", IF($AA14<TODAY(), "Late", "On Schedule")) -> Completed | AD14: 46356 | AE14: 0 | AF14: =IF($AE14=1, "Completed", IF($AD14<TODAY(), "Late", "On Schedule")) -> On Schedule | AG14: 46326 | AH14: 0 | AI14: =IF($AH14=1, "Completed", IF($AG14<TODAY(), "Late", "On Schedule")) -> On Schedule | AK14: =IFERROR(SUMPRODUCT(($M$1:$AH$1),(M14:AH14))/SUMIF((M14:AH14),"<>",($M$1:$AH$1)),"") -> 0.94588235 | AL14: =IF($AK14=1, "Completed", IF($K14<TODAY(), "Late", "On Schedule")) -> Late | AN14: =_xlfn.XLOOKUP($E14,'00 MASTER WORK REGISTER'!B:B,'00 MASTER WORK REGISTER'!N:N,"") -> 0 | AS14: MDW-39258 | AT14: MDW-69277 | AU14: MDW-69279
A15: 12 | B15: 12 | C15: MDW-39259 | D15: Lot01 | E15: GEN1.11 | F15: GEN | G15: Modification of Air Conditioning in CER and SER at OR23-OR29 | H15: ประธาน | K15: 46235 | L15: =O15-30 -> 46235 | M15: 1 | N15: =IF($M15=1, "Completed", IF($L15<TODAY(), "Late", "On Schedule")) -> Completed | O15: =U15-30 -> 46265 | P15: 1 | Q15: =IF($P15=1, "Completed", IF($O15<TODAY(), "Late", "On Schedule")) -> Completed | U15: 46295 | V15: 0.99 | W15: =IF($V15=1, "Completed", IF($U15<TODAY(), "Late", "On Schedule")) -> Late | AA15: 46295 | AB15: 1 | AC15: =IF($AB15=1, "Completed", IF($AA15<TODAY(), "Late", "On Schedule")) -> Completed | AD15: 46356 | AE15: 0 | AF15: =IF($AE15=1, "Completed", IF($AD15<TODAY(), "Late", "On Schedule")) -> On Schedule | AG15: 46326 | AH15: 0 | AI15: =IF($AH15=1, "Completed", IF($AG15<TODAY(), "Late", "On Schedule")) -> On Schedule | AK15: =IFERROR(SUMPRODUCT(($M$1:$AH$1),(M15:AH15))/SUMIF((M15:AH15),"<>",($M$1:$AH$1)),"") -> 0.94588235 | AL15: =IF($AK15=1, "Completed", IF($K15<TODAY(), "Late", "On Schedule")) -> Late | AN15: =_xlfn.XLOOKUP($E15,'00 MASTER WORK REGISTER'!B:B,'00 MASTER WORK REGISTER'!N:N,"") -> 0 | AS15: MDW-39259 | AT15: MDW-69277 | AU15: MDW-69280
A16: 13 | B16: 13 | C16: MDW-39272 | D16: Lot01 | E16: GEN1.12 | F16: GEN | G16: Modification of New M&E Room at IVS15 - IVS17 Civil & AR | H16: สหชาติ | K16: 46235 | L16: =O16-30 -> 46235 | M16: 1 | N16: =IF($M16=1, "Completed", IF($L16<TODAY(), "Late", "On Schedule")) -> Completed | O16: =U16-30 -> 46265 | P16: 1 | Q16: =IF($P16=1, "Completed", IF($O16<TODAY(), "Late", "On Schedule")) -> Completed | U16: 46295 | V16: 1 | W16: =IF($V16=1, "Completed", IF($U16<TODAY(), "Late", "On Schedule")) -> Completed | AA16: 46295 | AB16: 1 | AC16: =IF($AB16=1, "Completed", IF($AA16<TODAY(), "Late", "On Schedule")) -> Completed | AG16: 46326 | AH16: 0 | AI16: =IF($AH16=1, "Completed", IF($AG16<TODAY(), "Late", "On Schedule")) -> On Schedule | AK16: =IFERROR(SUMPRODUCT(($M$1:$AH$1),(M16:AH16))/SUMIF((M16:AH16),"<>",($M$1:$AH$1)),"") -> 0.96428571 | AL16: =IF($AK16=1, "Completed", IF($K16<TODAY(), "Late", "On Schedule")) -> Late | AN16: =_xlfn.XLOOKUP($E16,'00 MASTER WORK REGISTER'!B:B,'00 MASTER WORK REGISTER'!N:N,"") -> 0 | AS16: MDW-39272 | AT16: MDW-69299 | AU16: MDW-69300
A17: 14 | B17: 14 | C17: MDW-39273 | D17: Lot01 | E17: GEN1.13 | F17: GEN | G17: Modification of New M&E UPS Room at IVS15-IVS17 - Building Services | H17: ประธาน | K17: 46235 | L17: =O17-30 -> 46235 | M17: 1 | N17: =IF($M17=1, "Completed", IF($L17<TODAY(), "Late", "On Schedule")) -> Completed | O17: =U17-30 -> 46265 | P17: 1 | Q17: =IF($P17=1, "Completed", IF($O17<TODAY(), "Late", "On Schedule")) -> Completed | U17: 46295 | V17: 0.99 | W17: =IF($V17=1, "Completed", IF($U17<TODAY(), "Late", "On Schedule")) -> Late | AA17: 46295 | AB17: 1 | AC17: =IF($AB17=1, "Completed", IF($AA17<TODAY(), "Late", "On Schedule")) -> Completed | AD17: 46356 | AE17: 0 | AF17: =IF($AE17=1, "Completed", IF($AD17<TODAY(), "Late", "On Schedule")) -> On Schedule | AG17: 46326 | AH17: 0 | AI17: =IF($AH17=1, "Completed", IF($AG17<TODAY(), "Late", "On Schedule")) -> On Schedule | AK17: =IFERROR(SUMPRODUCT(($M$1:$AH$1),(M17:AH17))/SUMIF((M17:AH17),"<>",($M$1:$AH$1)),"") -> 0.94588235 | AL17: =IF($AK17=1, "Completed", IF($K17<TODAY(), "Late", "On Schedule")) -> Late | AN17: =_xlfn.XLOOKUP($E17,'00 MASTER WORK REGISTER'!B:B,'00 MASTER WORK REGISTER'!N:N,"") -> 0 | AS17: MDW-39273 | AT17: MDW-69301 | AU17: MDW-69302
A18: 15 | B18: 15 | C18: MDW-39294 | D18: Lot01 | E18: GEN1.14 | F18: GEN | G18: Provision of Architectural Work in new M&E UPS room at OR23 | H18: สหชาติ | K18: 46235 | L18: =O18-30 -> 46235 | M18: 1 | N18: =IF($M18=1, "Completed", IF($L18<TODAY(), "Late", "On Schedule")) -> Completed | O18: =U18-30 -> 46265 | P18: 1 | Q18: =IF($P18=1, "Completed", IF($O18<TODAY(), "Late", "On Schedule")) -> Completed | U18: 46295 | V18: 1 | W18: =IF($V18=1, "Completed", IF($U18<TODAY(), "Late", "On Schedule")) -> Completed | AA18: 46295 | AB18: 1 | AC18: =IF($AB18=1, "Completed", IF($AA18<TODAY(), "Late", "On Schedule")) -> Completed | AG18: 46326 | AH18: 0 | AI18: =IF($AH18=1, "Completed", IF($AG18<TODAY(), "Late", "On Schedule")) -> On Schedule | AK18: =IFERROR(SUMPRODUCT(($M$1:$AH$1),(M18:AH18))/SUMIF((M18:AH18),"<>",($M$1:$AH$1)),"") -> 0.96428571 | AL18: =IF($AK18=1, "Completed", IF($K18<TODAY(), "Late", "On Schedule")) -> Late | AN18: =_xlfn.XLOOKUP($E18,'00 MASTER WORK REGISTER'!B:B,'00 MASTER WORK REGISTER'!N:N,"") -> 0 | AS18: MDW-39294 | AT18: MDW-69339 | AU18: MDW-69340
A19: 16 | B19: 16 | C19: MDW-39299 | D19: Lot01 | E19: GEN1.15 | F19: GEN | G19: Provision of Air Conditioning System in Commercial Room at OR13-OR19 | H19: ประธาน | K19: 46235 | L19: =O19-30 -> 46235 | M19: 1 | N19: =IF($M19=1, "Completed", IF($L19<TODAY(), "Late", "On Schedule")) -> Completed | O19: =U19-30 -> 46265 | P19: 1 | Q19: =IF($P19=1, "Completed", IF($O19<TODAY(), "Late", "On Schedule")) -> Completed | U19: 46295 | V19: 1 | W19: =IF($V19=1, "Completed", IF($U19<TODAY(), "Late", "On Schedule")) -> Completed | AA19: 46295 | AB19: 1 | AC19: =IF($AB19=1, "Completed", IF($AA19<TODAY(), "Late", "On Schedule")) -> Completed | AD19: 46326 | AE19: 0 | AF19: =IF($AE19=1, "Completed", IF($AD19<TODAY(), "Late", "On Schedule")) -> On Schedule | AG19: 46326 | AH19: 0 | AI19: =IF($AH19=1, "Completed", IF($AG19<TODAY(), "Late", "On Schedule")) -> On Schedule | AK19: =IFERROR(SUMPRODUCT(($M$1:$AH$1),(M19:AH19))/SUMIF((M19:AH19),"<>",($M$1:$AH$1)),"") -> 0.95294118 | AL19: =IF($AK19=1, "Completed", IF($K19<TODAY(), "Late", "On Schedule")) -> Late | AN19: =_xlfn.XLOOKUP($E19,'00 MASTER WORK REGISTER'!B:B,'00 MASTER WORK REGISTER'!N:N,"") -> 0 | AS19: MDW-39299 | AT19: MDW-69349 | AU19: MDW-69350
A20: 17 | B20: 17 | C20: MDW-39306 | D20: Lot01 | E20: GEN1.16 | F20: GEN | G20: Modification CER and First Aid Room at OR14 - Building Services | H20: ประธาน | K20: 46235 | L20: =O20-30 -> 46235 | M20: 1 | N20: =IF($M20=1, "Completed", IF($L20<TODAY(), "Late", "On Schedule")) -> Completed | O20: =U20-30 -> 46265 | P20: 1 | Q20: =IF($P20=1, "Completed", IF($O20<TODAY(), "Late", "On Schedule")) -> Completed | U20: 46295 | V20: 1 | W20: =IF($V20=1, "Completed", IF($U20<TODAY(), "Late", "On Schedule")) -> Completed | AA20: 46295 | AB20: 1 | AC20: =IF($AB20=1, "Completed", IF($AA20<TODAY(), "Late", "On Schedule")) -> Completed | AD20: 46326 | AE20: 1 | AF20: =IF($AE20=1, "Completed", IF($AD20<TODAY(), "Late", "On Schedule")) -> Completed | AG20: 46326 | AH20: 0 | AI20: =IF($AH20=1, "Completed", IF($AG20<TODAY(), "Late", "On Schedule")) -> On Schedule | AK20: =IFERROR(SUMPRODUCT(($M$1:$AH$1),(M20:AH20))/SUMIF((M20:AH20),"<>",($M$1:$AH$1)),"") -> 0.96470588 | AL20: =IF($AK20=1, "Completed", IF($K20<TODAY(), "Late", "On Schedule")) -> Late | AN20: =_xlfn.XLOOKUP($E20,'00 MASTER WORK REGISTER'!B:B,'00 MASTER WORK REGISTER'!N:N,"") -> 0 | AS20: MDW-39306 | AT20: MDW-69363 | AU20: MDW-69364
A21: 18 | B21: 18 | C21: MDW-39307 | D21: Lot01 | E21: GEN1.17 | F21: GEN | G21: Additional Fence at Back of House OR13 - OR22 and IVS East Section | H21: สหชาติ | K21: 46235 | L21: 46295 | M21: 1 | N21: =IF($M21=1, "Completed", IF($L21<TODAY(), "Late", "On Schedule")) -> Completed | O21: 46326 | P21: 0.5 | Q21: =IF($P21=1, "Completed", IF($O21<TODAY(), "Late", "On Schedule")) -> On Schedule | U21: 46387 | V21: 0 | W21: =IF($V21=1, "Completed", IF($U21<TODAY(), "Late", "On Schedule")) -> On Schedule | AA21: 46295 | AB21: 1 | AC21: =IF($AB21=1, "Completed", IF($AA21<TODAY(), "Late", "On Schedule")) -> Completed | AG21: =U21+30 -> 46417 | AH21: 0 | AI21: =IF($AH21=1, "Completed", IF($AG21<TODAY(), "Late", "On Schedule")) -> On Schedule | AK21: =IFERROR(SUMPRODUCT(($M$1:$AH$1),(M21:AH21))/SUMIF((M21:AH21),"<>",($M$1:$AH$1)),"") -> 0.19047619 | AL21: =IF($AK21=1, "Completed", IF($K21<TODAY(), "Late", "On Schedule")) -> Late | AN21: =_xlfn.XLOOKUP($E21,'00 MASTER WORK REGISTER'!B:B,'00 MASTER WORK REGISTER'!N:N,"") -> 0 | AS21: MDW-39307 | AT21: MDW-69365 | AU21: MDW-69366
A22: 19 | B22: 19 | C22: MDW-39249 | D22: Lot01 | E22: GEN1.18 | F22: GEN | G22: SOR Counter and Workstation Hanging Support Installation on East Section | H22: สหชาติ | K22: 46235 | L22: 46235 | M22: 1 | N22: =IF($M22=1, "Completed", IF($L22<TODAY(), "Late", "On Schedule")) -> Completed | O22: 46265 | P22: 1 | Q22: =IF($P22=1, "Completed", IF($O22<TODAY(), "Late", "On Schedule")) -> Completed | U22: 46295 | V22: 1 | W22: =IF($V22=1, "Completed", IF($U22<TODAY(), "Late", "On Schedule")) -> Completed | AA22: 46295 | AB22: 1 | AC22: =IF($AB22=1, "Completed", IF($AA22<TODAY(), "Late", "On Schedule")) -> Completed | AG22: 46326 | AH22: 0 | AI22: =IF($AH22=1, "Completed", IF($AG22<TODAY(), "Late", "On Schedule")) -> On Schedule | AK22: =IFERROR(SUMPRODUCT(($M$1:$AH$1),(M22:AH22))/SUMIF((M22:AH22),"<>",($M$1:$AH$1)),"") -> 0.96428571 | AL22: =IF($AK22=1, "Completed", IF($K22<TODAY(), "Late", "On Schedule")) -> Late | AN22: =_xlfn.XLOOKUP($E22,'00 MASTER WORK REGISTER'!B:B,'00 MASTER WORK REGISTER'!N:N,"") | AO22: เพิ่ม Counter และ Workstation Hanging Support ที่ SOR at all Station | AS22: MDW-39249 | AT22: MDW-69263 | AU22: MDW-69264
A23: 20 | B23: 20 | C23: MDW-39250 | D23: Lot01 | E23: GEN1.19 | F23: GEN | G23: Ticket Office Modification on East Section | H23: สหชาติ | K23: 46235 | L23: 46235 | M23: 1 | N23: =IF($M23=1, "Completed", IF($L23<TODAY(), "Late", "On Schedule")) -> Completed | O23: 46265 | P23: 1 | Q23: =IF($P23=1, "Completed", IF($O23<TODAY(), "Late", "On Schedule")) -> Completed | U23: 46295 | V23: 1 | W23: =IF($V23=1, "Completed", IF($U23<TODAY(), "Late", "On Schedule")) -> Completed | AA23: 46295 | AB23: 1 | AC23: =IF($AB23=1, "Completed", IF($AA23<TODAY(), "Late", "On Schedule")) -> Completed | AG23: 46326 | AH23: 0 | AI23: =IF($AH23=1, "Completed", IF($AG23<TODAY(), "Late", "On Schedule")) -> On Schedule | AK23: =IFERROR(SUMPRODUCT(($M$1:$AH$1),(M23:AH23))/SUMIF((M23:AH23),"<>",($M$1:$AH$1)),"") -> 0.96428571 | AL23: =IF($AK23=1, "Completed", IF($K23<TODAY(), "Late", "On Schedule")) -> Late | AN23: =_xlfn.XLOOKUP($E23,'00 MASTER WORK REGISTER'!B:B,'00 MASTER WORK REGISTER'!N:N,"") -> 0 | AO23: ปรับ Raise floor เพื่อเพิ่มช่องว่างระหว่าง Counter กับพื้นให้ได้ 65cm. (รวมความสูงจากบนCounterถึงพื้นคือ75cm) ทำ Counter ใหม่ให้ได้ระดับกับ Raise floor (รวมรื้อ Counterเดิมออก) | AS23: MDW-39250 | AT23: MDW-69265 | AU23: MDW-69266
A24: 21 | B24: 21 | C24: =_xlfn.XLOOKUP($E24,'00 MASTER WORK REGISTER'!B:B,'00 MASTER WORK REGISTER'!L:L) -> MDW-39261 | D24: Lot01 | E24: GEN2 | F24: GEN | G24: =_xlfn.XLOOKUP($E24,'00 MASTER WORK REGISTER'!B:B,'00 MASTER WORK REGISTER'!H:H) -> Rooms and Building Service Systems Modification in Depot Area | H24: =_xlfn.XLOOKUP($E24,'00 MASTER WORK REGISTER'!B:B,'00 MASTER WORK REGISTER'!$I:$I,"") -> - | J24: Depot | K24: =_xlfn.XLOOKUP($E24,'00 MASTER WORK REGISTER'!$B:$B,'00 MASTER WORK REGISTER'!$M:$M,"") -> 46235 | AK24: =IFERROR(SUMPRODUCT(($M$1:$AH$1),(M24:AH24))/SUMIF((M24:AH24),"<>",($M$1:$AH$1)),"") | AN24: =_xlfn.XLOOKUP($E24,'00 MASTER WORK REGISTER'!B:B,'00 MASTER WORK REGISTER'!N:N,"") -> 0 | AP24: =_xlfn.XLOOKUP($F24,#REF!,#REF!,"") -> #REF! | AS24: MDW-39261 | AT24: =_xlfn.XLOOKUP($AS24,'02 Design'!F:F,'02 Design'!AE:AE," ") -> MDW-69283 | AU24: =_xlfn.XLOOKUP($AS24,'02 Design'!F:F,'02 Design'!AF:AF," ") -> MDW-69284
A25: 22 | B25: 22 | C25: MDW-39260 | D25: Lot01 | E25: GEN2.1 | F25: GEN | G25: Modification of Air Conditioning in M&E Room at OCC Building | H25: ประธาน | K25: 46235 | L25: 46021 | M25: 1 | N25: =IF($M25=1, "Completed", IF($L25<TODAY(), "Late", "On Schedule")) -> Completed | O25: 46051 | P25: 1 | Q25: =IF($P25=1, "Completed", IF($O25<TODAY(), "Late", "On Schedule")) -> Completed | U25: 46081 | V25: 1 | W25: =IF($V25=1, "Completed", IF($U25<TODAY(), "Late", "On Schedule")) -> Completed | AA25: 46295 | AB25: 1 | AC25: =IF($AB25=1, "Completed", IF($AA25<TODAY(), "Late", "On Schedule")) -> Completed | AD25: 46326 | AE25: 1 | AF25: =IF($AE25=1, "Completed", IF($AD25<TODAY(), "Late", "On Schedule")) -> Completed | AG25: 46326 | AH25: 0 | AI25: =IF($AH25=1, "Completed", IF($AG25<TODAY(), "Late", "On Schedule")) -> On Schedule | AK25: =IFERROR(SUMPRODUCT(($M$1:$AH$1),(M25:AH25))/SUMIF((M25:AH25),"<>",($M$1:$AH$1)),"") -> 0.96470588 | AL25: =IF($AK25=1, "Completed", IF($K25<TODAY(), "Late", "On Schedule")) -> Late | AN25: =_xlfn.XLOOKUP($E25,'00 MASTER WORK REGISTER'!B:B,'00 MASTER WORK REGISTER'!N:N,"") | AS25: MDW-39260 | AT25: MDW-69281 | AU25: MDW-69282
A26: 23 | B26: 23 | C26: MDW-39261 | D26: Lot01 | E26: GEN2.2 | F26: GEN | G26: Provision of UPS for MDB Control at Main Workshop, OCC Building, Admin Building, Stabling Yard and Train Washing Plant | H26: ประธาน | K26: 46235 | L26: 46266 | M26: 1 | N26: =IF($M26=1, "Completed", IF($L26<TODAY(), "Late", "On Schedule")) -> Completed | O26: 46296 | P26: 1 | Q26: =IF($P26=1, "Completed", IF($O26<TODAY(), "Late", "On Schedule")) -> Completed | U26: 46326 | V26: 0.9 | W26: =IF($V26=1, "Completed", IF($U26<TODAY(), "Late", "On Schedule")) -> On Schedule | AA26: 46295 | AB26: 1 | AC26: =IF($AB26=1, "Completed", IF($AA26<TODAY(), "Late", "On Schedule")) -> Completed | AD26: 46326 | AE26: 0 | AF26: =IF($AE26=1, "Completed", IF($AD26<TODAY(), "Late", "On Schedule")) -> On Schedule | AG26: =U26+30 -> 46356 | AH26: 0 | AI26: =IF($AH26=1, "Completed", IF($AG26<TODAY(), "Late", "On Schedule")) -> On Schedule | AK26: =IFERROR(SUMPRODUCT(($M$1:$AH$1),(M26:AH26))/SUMIF((M26:AH26),"<>",($M$1:$AH$1)),"") -> 0.88235294 | AL26: =IF($AK26=1, "Completed", IF($K26<TODAY(), "Late", "On Schedule")) -> Late | AN26: =_xlfn.XLOOKUP($E26,'00 MASTER WORK REGISTER'!B:B,'00 MASTER WORK REGISTER'!N:N,"") | AO26: Add small UPS for MDB Control at MMW/OCC/Admin/Stabling/Train Washing Plant | AS26: MDW-39261 | AT26: MDW-69283 | AU26: MDW-69284
A27: 24 | B27: 24 | C27: MDW-39262 | D27: Lot01 | E27: GEN2.3 | F27: GEN | G27: Provision of Redundant MDB at OCC Building, Admin Building and Canteen | H27: ประธาน | K27: 46235 | L27: 46266 | M27: 1 | N27: =IF($M27=1, "Completed", IF($L27<TODAY(), "Late", "On Schedule")) -> Completed | O27: 46296 | P27: 1 | Q27: =IF($P27=1, "Completed", IF($O27<TODAY(), "Late", "On Schedule")) -> Completed | U27: 46326 | V27: 0.95 | W27: =IF($V27=1, "Completed", IF($U27<TODAY(), "Late", "On Schedule")) -> On Schedule | AA27: 46295 | AB27: 1 | AC27: =IF($AB27=1, "Completed", IF($AA27<TODAY(), "Late", "On Schedule")) -> Completed | AD27: 46326 | AE27: 0 | AF27: =IF($AE27=1, "Completed", IF($AD27<TODAY(), "Late", "On Schedule")) -> On Schedule | AG27: =U27+30 -> 46356 | AH27: 0 | AI27: =IF($AH27=1, "Completed", IF($AG27<TODAY(), "Late", "On Schedule")) -> On Schedule | AK27: =IFERROR(SUMPRODUCT(($M$1:$AH$1),(M27:AH27))/SUMIF((M27:AH27),"<>",($M$1:$AH$1)),"") -> 0.91764706 | AL27: =IF($AK27=1, "Completed", IF($K27<TODAY(), "Late", "On Schedule")) -> Late | AN27: =_xlfn.XLOOKUP($E27,'00 MASTER WORK REGISTER'!B:B,'00 MASTER WORK REGISTER'!N:N,"") | AS27: MDW-39262 | AT27: MDW-69285 | AU27: MDW-69286
A28: 25 | B28: 25 | C28: MDW-39263 | D28: Lot01 | E28: GEN2.4 | F28: GEN | G28: Additonal Lighting System at Depot Area | H28: ประธาน | K28: 46235 | L28: 46113 | M28: 1 | N28: =IF($M28=1, "Completed", IF($L28<TODAY(), "Late", "On Schedule")) -> Completed | O28: 46143 | P28: 1 | Q28: =IF($P28=1, "Completed", IF($O28<TODAY(), "Late", "On Schedule")) -> Completed | U28: 46173 | V28: 1 | W28: =IF($V28=1, "Completed", IF($U28<TODAY(), "Late", "On Schedule")) -> Completed | AA28: 46295 | AB28: 1 | AC28: =IF($AB28=1, "Completed", IF($AA28<TODAY(), "Late", "On Schedule")) -> Completed | AD28: 46326 | AE28: 1 | AF28: =IF($AE28=1, "Completed", IF($AD28<TODAY(), "Late", "On Schedule")) -> Completed | AG28: 46326 | AH28: 0 | AI28: =IF($AH28=1, "Completed", IF($AG28<TODAY(), "Late", "On Schedule")) -> On Schedule | AK28: =IFERROR(SUMPRODUCT(($M$1:$AH$1),(M28:AH28))/SUMIF((M28:AH28),"<>",($M$1:$AH$1)),"") -> 0.96470588 | AL28: =IF($AK28=1, "Completed", IF($K28<TODAY(), "Late", "On Schedule")) -> Late | AN28: =_xlfn.XLOOKUP($E28,'00 MASTER WORK REGISTER'!B:B,'00 MASTER WORK REGISTER'!N:N,"") | AS28: MDW-39263 | AT28: MDW-69287 | AU28: MDW-69288
A29: 26 | B29: 26 | C29: MDW-39290 | D29: Lot01 | E29: GEN2.5 | F29: GEN | G29: Modification Room for PSY at Depot Buildings - Building Services | H29: ประธาน | K29: 46235 | L29: 46235 | M29: 1 | N29: =IF($M29=1, "Completed", IF($L29<TODAY(), "Late", "On Schedule")) -> Completed | O29: 46265 | P29: 1 | Q29: =IF($P29=1, "Completed", IF($O29<TODAY(), "Late", "On Schedule")) -> Completed | U29: 46295 | V29: 1 | W29: =IF($V29=1, "Completed", IF($U29<TODAY(), "Late", "On Schedule")) -> Completed | AA29: 46295 | AB29: 1 | AC29: =IF($AB29=1, "Completed", IF($AA29<TODAY(), "Late", "On Schedule")) -> Completed | AD29: 46326 | AE29: 0 | AF29: =IF($AE29=1, "Completed", IF($AD29<TODAY(), "Late", "On Schedule")) -> On Schedule | AG29: 46326 | AH29: 0 | AI29: =IF($AH29=1, "Completed", IF($AG29<TODAY(), "Late", "On Schedule")) -> On Schedule | AK29: =IFERROR(SUMPRODUCT(($M$1:$AH$1),(M29:AH29))/SUMIF((M29:AH29),"<>",($M$1:$AH$1)),"") -> 0.95294118 | AL29: =IF($AK29=1, "Completed", IF($K29<TODAY(), "Late", "On Schedule")) -> Late | AN29: =_xlfn.XLOOKUP($E29,'00 MASTER WORK REGISTER'!B:B,'00 MASTER WORK REGISTER'!N:N,"") | AS29: MDW-39290 | AT29: MDW-69331 | AU29: MDW-69332
A30: 27 | B30: 27 | C30: MDW-39300 | D30: Lot01 | E30: GEN2.6 | F30: GEN | G30: Modification SIG-PSD Office at Main Workshop - Building Services | H30: ประธาน | K30: 46235 | L30: 46235 | M30: 1 | N30: =IF($M30=1, "Completed", IF($L30<TODAY(), "Late", "On Schedule")) -> Completed | O30: 46265 | P30: 1 | Q30: =IF($P30=1, "Completed", IF($O30<TODAY(), "Late", "On Schedule")) -> Completed | U30: 46295 | V30: 1 | W30: =IF($V30=1, "Completed", IF($U30<TODAY(), "Late", "On Schedule")) -> Completed | AA30: 46295 | AB30: 1 | AC30: =IF($AB30=1, "Completed", IF($AA30<TODAY(), "Late", "On Schedule")) -> Completed | AD30: 46326 | AE30: 0 | AF30: =IF($AE30=1, "Completed", IF($AD30<TODAY(), "Late", "On Schedule")) -> On Schedule | AG30: 46326 | AH30: 0 | AI30: =IF($AH30=1, "Completed", IF($AG30<TODAY(), "Late", "On Schedule")) -> On Schedule | AK30: =IFERROR(SUMPRODUCT(($M$1:$AH$1),(M30:AH30))/SUMIF((M30:AH30),"<>",($M$1:$AH$1)),"") -> 0.95294118 | AL30: =IF($AK30=1, "Completed", IF($K30<TODAY(), "Late", "On Schedule")) -> Late | AN30: =_xlfn.XLOOKUP($E30,'00 MASTER WORK REGISTER'!B:B,'00 MASTER WORK REGISTER'!N:N,"") | AS30: MDW-39300 | AT30: MDW-69351 | AU30: MDW-69352
A31: 28 | B31: 28 | C31: MDW-39301 | D31: Lot01 | E31: GEN2.7 | F31: GEN | G31: Modification Backup CCR Room at Main Workshop - Building Services | H31: ประธาน | K31: 46235 | L31: 46235 | M31: 1 | N31: =IF($M31=1, "Completed", IF($L31<TODAY(), "Late", "On Schedule")) -> Completed | O31: 46265 | P31: 1 | Q31: =IF($P31=1, "Completed", IF($O31<TODAY(), "Late", "On Schedule")) -> Completed | U31: 46295 | V31: 1 | W31: =IF($V31=1, "Completed", IF($U31<TODAY(), "Late", "On Schedule")) -> Completed | AA31: 46295 | AB31: 1 | AC31: =IF($AB31=1, "Completed", IF($AA31<TODAY(), "Late", "On Schedule")) -> Completed | AD31: 46326 | AE31: 0 | AF31: =IF($AE31=1, "Completed", IF($AD31<TODAY(), "Late", "On Schedule")) -> On Schedule | AG31: 46326 | AH31: 0 | AI31: =IF($AH31=1, "Completed", IF($AG31<TODAY(), "Late", "On Schedule")) -> On Schedule | AK31: =IFERROR(SUMPRODUCT(($M$1:$AH$1),(M31:AH31))/SUMIF((M31:AH31),"<>",($M$1:$AH$1)),"") -> 0.95294118 | AL31: =IF($AK31=1, "Completed", IF($K31<TODAY(), "Late", "On Schedule")) -> Late | AN31: =_xlfn.XLOOKUP($E31,'00 MASTER WORK REGISTER'!B:B,'00 MASTER WORK REGISTER'!N:N,"") | AS31: MDW-39301 | AT31: MDW-69353 | AU31: MDW-69354
A32: 29 | B32: 29 | C32: MDW-39302 | D32: Lot01 | E32: GEN2.8 | F32: GEN | G32: Modification SER at Main Workshop - Building Services | H32: ประธาน | K32: 46235 | L32: 46235 | M32: 1 | N32: =IF($M32=1, "Completed", IF($L32<TODAY(), "Late", "On Schedule")) -> Completed | O32: 46265 | P32: 1 | Q32: =IF($P32=1, "Completed", IF($O32<TODAY(), "Late", "On Schedule")) -> Completed | U32: 46295 | V32: 1 | W32: =IF($V32=1, "Completed", IF($U32<TODAY(), "Late", "On Schedule")) -> Completed | AA32: 46295 | AB32: 1 | AC32: =IF($AB32=1, "Completed", IF($AA32<TODAY(), "Late", "On Schedule")) -> Completed | AD32: 46326 | AE32: 0 | AF32: =IF($AE32=1, "Completed", IF($AD32<TODAY(), "Late", "On Schedule")) -> On Schedule | AG32: 46326 | AH32: 0 | AI32: =IF($AH32=1, "Completed", IF($AG32<TODAY(), "Late", "On Schedule")) -> On Schedule | AK32: =IFERROR(SUMPRODUCT(($M$1:$AH$1),(M32:AH32))/SUMIF((M32:AH32),"<>",($M$1:$AH$1)),"") -> 0.95294118 | AL32: =IF($AK32=1, "Completed", IF($K32<TODAY(), "Late", "On Schedule")) -> Late | AN32: =_xlfn.XLOOKUP($E32,'00 MASTER WORK REGISTER'!B:B,'00 MASTER WORK REGISTER'!N:N,"") | AS32: MDW-39302 | AT32: MDW-69355 | AU32: MDW-69356
A33: 30 | B33: 30 | C33: MDW-39303 | D33: Lot01 | E33: GEN2.9 | F33: GEN | G33: Modification CER & SCADA Room at Main Workshop - Building Services | H33: ประธาน | K33: 46235 | L33: 46235 | M33: 1 | N33: =IF($M33=1, "Completed", IF($L33<TODAY(), "Late", "On Schedule")) -> Completed | O33: 46265 | P33: 1 | Q33: =IF($P33=1, "Completed", IF($O33<TODAY(), "Late", "On Schedule")) -> Completed | U33: 46295 | V33: 1 | W33: =IF($V33=1, "Completed", IF($U33<TODAY(), "Late", "On Schedule")) -> Completed | AA33: 46295 | AB33: 1 | AC33: =IF($AB33=1, "Completed", IF($AA33<TODAY(), "Late", "On Schedule")) -> Completed | AD33: 46326 | AE33: 0 | AF33: =IF($AE33=1, "Completed", IF($AD33<TODAY(), "Late", "On Schedule")) -> On Schedule | AG33: 46326 | AH33: 0 | AI33: =IF($AH33=1, "Completed", IF($AG33<TODAY(), "Late", "On Schedule")) -> On Schedule | AK33: =IFERROR(SUMPRODUCT(($M$1:$AH$1),(M33:AH33))/SUMIF((M33:AH33),"<>",($M$1:$AH$1)),"") -> 0.95294118 | AL33: =IF($AK33=1, "Completed", IF($K33<TODAY(), "Late", "On Schedule")) -> Late | AN33: =_xlfn.XLOOKUP($E33,'00 MASTER WORK REGISTER'!B:B,'00 MASTER WORK REGISTER'!N:N,"") | AS33: MDW-39303 | AT33: MDW-69357 | AU33: MDW-69358
A34: 31 | B34: 31 | C34: MDW-39309 | D34: Lot01 | E34: GEN2.10 | F34: GEN | G34: Modification Air Conditioning System at CCR | H34: ประธาน | K34: 46235 | L34: 46296 | M34: 1 | N34: =IF($M34=1, "Completed", IF($L34<TODAY(), "Late", "On Schedule")) -> Completed | O34: 46326 | P34: 1 | Q34: =IF($P34=1, "Completed", IF($O34<TODAY(), "Late", "On Schedule")) -> Completed | U34: 46387 | V34: 0.8 | W34: =IF($V34=1, "Completed", IF($U34<TODAY(), "Late", "On Schedule")) -> On Schedule | AA34: 46295 | AB34: 1 | AC34: =IF($AB34=1, "Completed", IF($AA34<TODAY(), "Late", "On Schedule")) -> Completed | AD34: 46326 | AE34: 0 | AF34: =IF($AE34=1, "Completed", IF($AD34<TODAY(), "Late", "On Schedule")) -> On Schedule | AG34: =U34+30 -> 46417 | AH34: 0 | AI34: =IF($AH34=1, "Completed", IF($AG34<TODAY(), "Late", "On Schedule")) -> On Schedule | AK34: =IFERROR(SUMPRODUCT(($M$1:$AH$1),(M34:AH34))/SUMIF((M34:AH34),"<>",($M$1:$AH$1)),"") -> 0.81176471 | AL34: =IF($AK34=1, "Completed", IF($K34<TODAY(), "Late", "On Schedule")) -> Late | AN34: =_xlfn.XLOOKUP($E34,'00 MASTER WORK REGISTER'!B:B,'00 MASTER WORK REGISTER'!N:N,"") | AS34: MDW-39309 | AT34: MDW-69369 | AU34: MDW-69370
A35: 32 | B35: 32 | C35: MDW-39312 | D35: Lot01 | E35: GEN2.11 | F35: GEN | G35: Modification Electronic Workshop at Main Workshop - Building Services | H35: ประธาน | K35: 46235 | L35: 46326 | M35: 1 | N35: =IF($M35=1, "Completed", IF($L35<TODAY(), "Late", "On Schedule")) -> Completed | O35: 46356 | P35: 1 | Q35: =IF($P35=1, "Completed", IF($O35<TODAY(), "Late", "On Schedule")) -> Completed | U35: 46387 | V35: 0 | W35: =IF($V35=1, "Completed", IF($U35<TODAY(), "Late", "On Schedule")) -> On Schedule | AA35: 46356 | AB35: 0 | AC35: =IF($AB35=1, "Completed", IF($AA35<TODAY(), "Late", "On Schedule")) -> On Schedule | AD35: 46326 | AE35: 0 | AF35: =IF($AE35=1, "Completed", IF($AD35<TODAY(), "Late", "On Schedule")) -> On Schedule | AG35: =U35+30 -> 46417 | AH35: 0 | AI35: =IF($AH35=1, "Completed", IF($AG35<TODAY(), "Late", "On Schedule")) -> On Schedule | AK35: =IFERROR(SUMPRODUCT(($M$1:$AH$1),(M35:AH35))/SUMIF((M35:AH35),"<>",($M$1:$AH$1)),"") -> 0.23529412 | AL35: =IF($AK35=1, "Completed", IF($K35<TODAY(), "Late", "On Schedule")) -> Late | AN35: =_xlfn.XLOOKUP($E35,'00 MASTER WORK REGISTER'!B:B,'00 MASTER WORK REGISTER'!N:N,"") | AS35: MDW-39312 | AT35: MDW-69375 | AU35: MDW-69376
A36: 33 | B36: 33 | C36: MDW-39313 | D36: Lot01 | E36: GEN2.12 | F36: GEN | G36: Modification Battery Charger Room at Main Workshop - Building Services | H36: ประธาน | K36: 46235 | L36: 46326 | M36: 1 | N36: =IF($M36=1, "Completed", IF($L36<TODAY(), "Late", "On Schedule")) -> Completed | O36: 46356 | P36: 1 | Q36: =IF($P36=1, "Completed", IF($O36<TODAY(), "Late", "On Schedule")) -> Completed | U36: 46387 | V36: 0 | W36: =IF($V36=1, "Completed", IF($U36<TODAY(), "Late", "On Schedule")) -> On Schedule | AA36: 46356 | AB36: 0 | AC36: =IF($AB36=1, "Completed", IF($AA36<TODAY(), "Late", "On Schedule")) -> On Schedule | AD36: 46326 | AE36: 0 | AF36: =IF($AE36=1, "Completed", IF($AD36<TODAY(), "Late", "On Schedule")) -> On Schedule | AG36: =U36+30 -> 46417 | AH36: 0 | AI36: =IF($AH36=1, "Completed", IF($AG36<TODAY(), "Late", "On Schedule")) -> On Schedule | AK36: =IFERROR(SUMPRODUCT(($M$1:$AH$1),(M36:AH36))/SUMIF((M36:AH36),"<>",($M$1:$AH$1)),"") -> 0.23529412 | AL36: =IF($AK36=1, "Completed", IF($K36<TODAY(), "Late", "On Schedule")) -> Late | AN36: =_xlfn.XLOOKUP($E36,'00 MASTER WORK REGISTER'!B:B,'00 MASTER WORK REGISTER'!N:N,"") | AS36: MDW-39313 | AT36: MDW-69377 | AU36: MDW-69378
A37: 34 | B37: 34 | C37: MDW-39314 | D37: Lot01 | E37: GEN2.13 | F37: GEN | G37: Modification Machining Room at Main Workshop - Building Services | H37: ประธาน | K37: 46235 | L37: 46326 | M37: 0.9 | N37: =IF($M37=1, "Completed", IF($L37<TODAY(), "Late", "On Schedule")) -> On Schedule | O37: 46356 | P37: 0 | Q37: =IF($P37=1, "Completed", IF($O37<TODAY(), "Late", "On Schedule")) -> On Schedule | U37: 46387 | V37: 0 | W37: =IF($V37=1, "Completed", IF($U37<TODAY(), "Late", "On Schedule")) -> On Schedule | AA37: 46356 | AB37: 0 | AC37: =IF($AB37=1, "Completed", IF($AA37<TODAY(), "Late", "On Schedule")) -> On Schedule | AD37: 46326 | AE37: 0 | AF37: =IF($AE37=1, "Completed", IF($AD37<TODAY(), "Late", "On Schedule")) -> On Schedule | AG37: =U37+30 -> 46417 | AH37: 0 | AI37: =IF($AH37=1, "Completed", IF($AG37<TODAY(), "Late", "On Schedule")) -> On Schedule | AK37: =IFERROR(SUMPRODUCT(($M$1:$AH$1),(M37:AH37))/SUMIF((M37:AH37),"<>",($M$1:$AH$1)),"") -> 0.10588235 | AL37: =IF($AK37=1, "Completed", IF($K37<TODAY(), "Late", "On Schedule")) -> Late | AN37: =_xlfn.XLOOKUP($E37,'00 MASTER WORK REGISTER'!B:B,'00 MASTER WORK REGISTER'!N:N,"") | AS37: MDW-39314 | AT37: MDW-69379 | AU37: MDW-69380
A38: 35 | B38: 35 | C38: MDW-39315 | D38: Lot01 | E38: GEN2.14 | F38: GEN | G38: Modification Electronic Workshop, Battery Charger and Machining Room at Main Workshop - Civil & AR | H38: สหชาติ | K38: 46235 | L38: 46326 | M38: 0.7 | N38: =IF($M38=1, "Completed", IF($L38<TODAY(), "Late", "On Schedule")) -> On Schedule | O38: 46356 | P38: 0.9 | Q38: =IF($P38=1, "Completed", IF($O38<TODAY(), "Late", "On Schedule")) -> On Schedule | U38: 46387 | V38: 0 | W38: =IF($V38=1, "Completed", IF($U38<TODAY(), "Late", "On Schedule")) -> On Schedule | AA38: 46356 | AB38: 0 | AC38: =IF($AB38=1, "Completed", IF($AA38<TODAY(), "Late", "On Schedule")) -> On Schedule | AG38: =U38+30 -> 46417 | AH38: 0 | AI38: =IF($AH38=1, "Completed", IF($AG38<TODAY(), "Late", "On Schedule")) -> On Schedule | AK38: =IFERROR(SUMPRODUCT(($M$1:$AH$1),(M38:AH38))/SUMIF((M38:AH38),"<>",($M$1:$AH$1)),"") -> 0.19047619 | AL38: =IF($AK38=1, "Completed", IF($K38<TODAY(), "Late", "On Schedule")) -> Late | AN38: =_xlfn.XLOOKUP($E38,'00 MASTER WORK REGISTER'!B:B,'00 MASTER WORK REGISTER'!N:N,"") | AS38: MDW-39315 | AT38: MDW-69383 | AU38: MDW-69384
A39: 36 | B39: 36 | C39: MDW-39297 | D39: Lot01 | E39: GEN2.15 | F39: GEN | G39: Training Room at Ratchada Station (Part 2) | H39: สหชาติ | K39: 46235 | L39: 46235 | M39: 0 | N39: =IF($M39=1, "Completed", IF($L39<TODAY(), "Late", "On Schedule")) -> Late | O39: 46265 | P39: 1 | Q39: =IF($P39=1, "Completed", IF($O39<TODAY(), "Late", "On Schedule")) -> Completed | U39: 46295 | V39: 1 | W39: =IF($V39=1, "Completed", IF($U39<TODAY(), "Late", "On Schedule")) -> Completed | AA39: 46356 | AB39: 0 | AC39: =IF($AB39=1, "Completed", IF($AA39<TODAY(), "Late", "On Schedule")) -> On Schedule | AG39: =U39+30 -> 46325 | AH39: 0 | AI39: =IF($AH39=1, "Completed", IF($AG39<TODAY(), "Late", "On Schedule")) -> On Schedule | AK39: =IFERROR(SUMPRODUCT(($M$1:$AH$1),(M39:AH39))/SUMIF((M39:AH39),"<>",($M$1:$AH$1)),"") -> 0.83333333 | AL39: =IF($AK39=1, "Completed", IF($K39<TODAY(), "Late", "On Schedule")) -> Late | AN39: =_xlfn.XLOOKUP($E39,'00 MASTER WORK REGISTER'!B:B,'00 MASTER WORK REGISTER'!N:N,"") | AS39: MDW-39297 | AT39: MDW-69345 | AU39: MDW-69346
A40: 37 | B40: 37 | C40: MDW-39291 | D40: Lot01 | E40: GEN2.16 | F40: GEN | G40: Conductor Rail Arrangement Modification at Main Line East Section | H40: กำพล | K40: 46235 | L40: 46295 | M40: 1 | N40: =IF($M40=1, "Completed", IF($L40<TODAY(), "Late", "On Schedule")) -> Completed | O40: 46295 | P40: 1 | Q40: =IF($P40=1, "Completed", IF($O40<TODAY(), "Late", "On Schedule")) -> Completed | U40: 46387 | V40: 0.9 | W40: =IF($V40=1, "Completed", IF($U40<TODAY(), "Late", "On Schedule")) -> On Schedule | AA40: 46356 | AB40: 0 | AC40: =IF($AB40=1, "Completed", IF($AA40<TODAY(), "Late", "On Schedule")) -> On Schedule | AG40: =U40+30 -> 46417 | AH40: 0 | AI40: =IF($AH40=1, "Completed", IF($AG40<TODAY(), "Late", "On Schedule")) -> On Schedule | AK40: =IFERROR(SUMPRODUCT(($M$1:$AH$1),(M40:AH40))/SUMIF((M40:AH40),"<>",($M$1:$AH$1)),"") -> 0.88095238 | AL40: =IF($AK40=1, "Completed", IF($K40<TODAY(), "Late", "On Schedule")) -> Late | AN40: =_xlfn.XLOOKUP($E40,'00 MASTER WORK REGISTER'!B:B,'00 MASTER WORK REGISTER'!N:N,"") | AS40: MDW-39291 | AT40: MDW-69333 | AU40: MDW-69334
...

Sheet ตามงาน
C2: บัณฑิต
B4: No. | C4: Design Submission | D4: Lot No. | E4: Code | F4: Activity Name | G4: CK Responsible Person | H4: Expected Completion Month | I4: Design (PLAN) | J4: Design (%) | K4: Design (Status) | L4: Procurement (PLAN) | M4: Procurement (%) | N4: Procurement (Status) | O4: Construction /Installation (PLAN) | P4: Construction /Installation (%) | Q4: Construction /Installation (Status) | R4: Note
B5: 113 | C5: MDW-39237 | D5: Lot01 | E5: GEN22 | F5: Central BEMS for the MRT Orange Line System | G5: บัณฑิต | H5: 46255 | I5: 46142 | J5: 0 | K5: Late | L5: 46203 | M5: 0 | N5: Late | O5: 46249 | P5: 0 | Q5: Late | R5: PPR Oct-26 กำลังเปรียบเทียบ Spec
C6: MDW-39283 | D6: Lot01 | E6: COM2 | F6: Intercom System in Cash Handling Room (if require) | G6: บัณฑิต | H6: 46375 | I6: 45930 | J6: 1 | K6: Completed | L6: 46203 | M6: 0.5 | N6: Late | O6: 46326 | P6: 0 | Q6: On Schedule | R6: รอพื้นที่เข้าติดตั้ง
C7: AFC-39001 | D7: Lot01 | E7: COM7 | F7: Mini Paging in Ticket Office | G7: บัณฑิต | H7: 46375 | I7: 45910 | J7: 1 | K7: Completed | L7: 46203 | M7: 1 | N7: Completed | O7: 46295 | P7: 0 | Q7: Late | R7: ของมาแล้ว รอพื้นที่เข้าติดตั้ง
C8: - | D8: Lot02 | E8: MO-BEM34 | F8: Access Gate (Full Height Turnstile) at 1st floor admin ORL | G8: บัณฑิต | H8: 46388 | I8: 46354 | J8: 1 | K8: Completed | L8: 46355 | M8: 1 | N8: Completed | O8: 46387 | P8: 0 | Q8: On Schedule
C9: - | D9: Lot02 | E9: MO-BEM35 | F9: Access Gate (Tripod with Swing Gate) at MWS Entrance | G9: บัณฑิต | H9: 46388 | I9: 46354 | J9: 1 | K9: Completed | L9: 46355 | M9: 1 | N9: Completed | O9: 46387 | P9: 0 | Q9: On Schedule | R9: TMD เริ่มเข้าทำช่วงเดือน Oct-26 (CIV จบ)
C10: - | D10: Lot02 | E10: MO-BEM36 | F10: Access Gate (Tripod with Swing Gate) at Admin 2nd floor connect to OCC | G10: บัณฑิต | H10: 46388 | I10: 46354 | J10: 1 | K10: Completed | L10: 46355 | M10: 1 | N10: Completed | O10: 46387 | P10: 0 | Q10: On Schedule | R10: TMD เริ่มเข้าทำช่วงเดือน Oct-26 (CIV จบ)
C11: - | D11: Lot02 | E11: MO-BEM37 | F11: Access Gate (Tripod with Swing Gate) on Klong Chourdyai bridge | G11: บัณฑิต | H11: 46388 | I11: 46354 | J11: 1 | K11: Completed | L11: 46355 | M11: 1 | N11: Completed | O11: 46387 | P11: 0 | Q11: On Schedule | R11: TMD เริ่มเข้าทำช่วงเดือน Oct-26 (CIV จบ)
C12: - | D12: Lot02 | E12: MO-BEM38 | F12: Access Gate (Tripod with roof covering) at parking lot OCC | G12: บัณฑิต | H12: 46388 | I12: 46354 | J12: 1 | K12: Completed | L12: 46355 | M12: 1 | N12: Completed | O12: 46387 | P12: 0 | Q12: On Schedule | R12: TMD เริ่มเข้าทำช่วงเดือน Oct-26 (CIV จบ)
C13: - | D13: Lot02 | E13: MO-BEM39 | F13: Access Gate (Tripod with roof covering) at Stair up to Depot slab | G13: บัณฑิต | H13: 46388 | I13: 46354 | J13: 1 | K13: Completed | L13: 46355 | M13: 1 | N13: Completed | O13: 46387 | P13: 0 | Q13: On Schedule | R13: TMD เริ่มเข้าทำช่วงเดือน Oct-26 (CIV จบ)
C14: - | D14: Lot02 | E14: MO-BEM40 | F14: Access Control (2 Factors, Card + Finger Print) at High Security rooms - CCR/PTR/Store | G14: บัณฑิต | H14: 46388 | I14: 46354 | J14: 1 | K14: Completed | L14: 46355 | M14: 1 | N14: Completed | O14: 46387 | P14: 0 | Q14: On Schedule | R14: STE เริ่มเข้าทำช่วงเดือน Oct-26
